<sdf version='1.7'>
  <model name='FLF'>
    <link name='base_footprint'>
      <inertial>
        <pose>1.485 0 0.385892 0 -0 0</pose>
        <mass>6.5</mass>
        <inertia>
          <ixx>0.268206</ixx>
          <ixy>-1.6237e-17</ixy>
          <ixz>0.009072</ixz>
          <iyy>7.97406</iyy>
          <iyz>-1.53723e-20</iyz>
          <izz>8.20975</izz>
        </inertia>
      </inertial>
      <collision name='base_footprint_fixed_joint_lump__base_link_collision'>
        <pose>0 0 0.387 0 -0 0</pose>
        <geometry>
          <box>
            <size>1.44 2.7 0.09</size>
          </box>
        </geometry>
      </collision>
      <collision name='base_footprint_fixed_joint_lump__ir_link_collision_1'>
        <pose>2.655 0 0.387 0 -0 0</pose>
        <geometry>
          <box>
            <size>0.81 2.43 0.09</size>
          </box>
        </geometry>
      </collision>
      <collision name='base_footprint_fixed_joint_lump__ir_sensor_1_collision_2'>
        <pose>2.835 0 0.315 0 -0 0</pose>
        <geometry>
          <box>
            <size>0.18 0.054 0.054</size>
          </box>
        </geometry>
      </collision>
      <collision name='base_footprint_fixed_joint_lump__ir_sensor_2_collision_3'>
        <pose>2.745 0.486 0.387 0 -0 0</pose>
        <geometry>
          <box>
            <size>0.18 0.054 0.054</size>
          </box>
        </geometry>
      </collision>
      <collision name='base_footprint_fixed_joint_lump__ir_sensor_3_collision_4'>
        <pose>2.745 0.972 0.387 0 -0 0</pose>
        <geometry>
          <box>
            <size>0.18 0.054 0.054</size>
          </box>
        </geometry>
      </collision>
      <collision name='base_footprint_fixed_joint_lump__ir_sensor_4_collision_5'>
        <pose>2.745 -0.486 0.387 0 -0 0</pose>
        <geometry>
          <box>
            <size>0.18 0.054 0.054</size>
          </box>
        </geometry>
      </collision>
      <collision name='base_footprint_fixed_joint_lump__ir_sensor_5_collision_6'>
        <pose>2.745 -0.972 0.387 0 -0 0</pose>
        <geometry>
          <box>
            <size>0.18 0.054 0.054</size>
          </box>
        </geometry>
      </collision>
      <collision name='base_footprint_fixed_joint_lump__neck_link_collision_7'>
        <pose>1.485 0 0.387 0 -0 0</pose>
        <geometry>
          <box>
            <size>1.53 0.9 0.09</size>
          </box>
        </geometry>
      </collision>
      <collision name='base_footprint_fixed_joint_lump__caster_wheel_collision_8'>
        <pose>1.485 0 0.144 0 -0 0</pose>
        <geometry>
          <sphere>
            <radius>0.1935</radius>
          </sphere>
        </geometry>
      </collision>
      <visual name='base_footprint_fixed_joint_lump__base_link_visual'>
        <pose>0 0 0.387 0 -0 0</pose>
        <geometry>
          <box>
            <size>1.44 2.7 0.09</size>
          </box>
        </geometry>
      </visual>
      <visual name='base_footprint_fixed_joint_lump__ir_link_visual_1'>
        <pose>2.655 0 0.387 0 -0 0</pose>
        <geometry>
          <box>
            <size>0.81 2.43 0.09</size>
          </box>
        </geometry>
      </visual>
      <visual name='base_footprint_fixed_joint_lump__ir_sensor_1_visual_2'>
        <pose>2.745 0 0.315 0 -0 0</pose>
        <geometry>
          <box>
            <size>0.18 0.054 0.054</size>
          </box>
        </geometry>
      </visual>
      <visual name='base_footprint_fixed_joint_lump__ir_sensor_2_visual_3'>
        <pose>2.745 0.486 0.477 0 -0 0</pose>
        <geometry>
          <box>
            <size>0.18 0.054 0.054</size>
          </box>
        </geometry>
      </visual>
      <visual name='base_footprint_fixed_joint_lump__ir_sensor_3_visual_4'>
        <pose>2.745 0.972 0.477 0 -0 0</pose>
        <geometry>
          <box>
            <size>0.18 0.054 0.054</size>
          </box>
        </geometry>
      </visual>
      <visual name='base_footprint_fixed_joint_lump__ir_sensor_4_visual_5'>
        <pose>2.745 -0.486 0.477 0 -0 0</pose>
        <geometry>
          <box>
            <size>0.18 0.054 0.054</size>
          </box>
        </geometry>
      </visual>
      <visual name='base_footprint_fixed_joint_lump__ir_sensor_5_visual_6'>
        <pose>2.745 -0.972 0.477 0 -0 0</pose>
        <geometry>
          <box>
            <size>0.18 0.054 0.054</size>
          </box>
        </geometry>
      </visual>
      <visual name='base_footprint_fixed_joint_lump__neck_link_visual_7'>
        <pose>1.485 0 0.387 0 -0 0</pose>
        <geometry>
          <box>
            <size>1.53 0.9 0.09</size>
          </box>
        </geometry>
      </visual>
      <visual name='base_footprint_fixed_joint_lump__caster_wheel_visual_8'>
        <pose>1.485 0 0.144 0 -0 0</pose>
        <geometry>
          <sphere>
            <radius>0.1935</radius>
          </sphere>
        </geometry>
      </visual>
      <visual name='base_footprint_fixed_joint_lump__test_link_visual_9'>
        <pose>0 0 0.8496 0 -0 0</pose>
        <geometry>
          <box>
            <size>0.18 0.54 0.9</size>
          </box>
        </geometry>
      </visual>
      <sensor name='test_sensor' type='ray'>
        <update_rate>30</update_rate>
        <visualize>1</visualize>
        <ray>
          <scan>
            <horizontal>
              <samples>10</samples>
              <resolution>1</resolution>
              <min_angle>-0.1</min_angle>
              <max_angle>0.1</max_angle>
            </horizontal>
          </scan>
          <range>
            <min>0.01</min>
            <max>1</max>
            <resolution>0.01</resolution>
          </range>
        </ray>
        <plugin name='sensor_plugin' filename='libgazebo_ros_laser.so'>
          <topicName>test_sensor</topicName>
          <frameName>sensor_link</frameName>
        </plugin>
        <pose>0 0 0.8496 0 -0 0</pose>
      </sensor>
    </link>
    <joint name='base_left_wheel_joint' type='revolute'>
      <pose relative_to='base_footprint'>0 1.485 0.387 -1.5708 0 0</pose>
      <parent>base_footprint</parent>
      <child>left_wheel</child>
      <axis>
        <xyz>0 0 1</xyz>
        <limit>
          <lower>-1e+16</lower>
          <upper>1e+16</upper>
        </limit>
        <dynamics>
          <damping>0.5</damping>
          <friction>0.5</friction>
          <spring_reference>0</spring_reference>
          <spring_stiffness>0</spring_stiffness>
        </dynamics>
      </axis>
    </joint>
    <link name='left_wheel'>
      <pose relative_to='base_left_wheel_joint'>0 0 0 0 -0 0</pose>
      <inertial>
        <pose>0 0 0 0 -0 0</pose>
        <mass>0.1</mass>
        <inertia>
          <ixx>1e-05</ixx>
          <ixy>0</ixy>
          <ixz>0</ixz>
          <iyy>1e-05</iyy>
          <iyz>0</iyz>
          <izz>2e-05</izz>
        </inertia>
      </inertial>
      <collision name='left_wheel_collision'>
        <pose>0 0 0 0 -0 0</pose>
        <geometry>
          <cylinder>
            <length>0.27</length>
            <radius>0.387</radius>
          </cylinder>
        </geometry>
        <surface>
          <contact>
            <ode>
              <kp>1000</kp>
              <kd>100</kd>
            </ode>
          </contact>
          <friction>
            <ode>
              <mu>1</mu>
              <mu2>1</mu2>
            </ode>
          </friction>
        </surface>
      </collision>
      <visual name='left_wheel_visual'>
        <pose>0 0 0 0 -0 0</pose>
        <geometry>
          <cylinder>
            <length>0.27</length>
            <radius>0.387</radius>
          </cylinder>
        </geometry>
      </visual>
    </link>
    <joint name='base_right_wheel_joint' type='revolute'>
      <pose relative_to='base_footprint'>0 -1.485 0.387 -1.5708 0 0</pose>
      <parent>base_footprint</parent>
      <child>right_wheel</child>
      <axis>
        <xyz>0 0 1</xyz>
        <limit>
          <lower>-1e+16</lower>
          <upper>1e+16</upper>
        </limit>
        <dynamics>
          <damping>0.5</damping>
          <friction>0.5</friction>
          <spring_reference>0</spring_reference>
          <spring_stiffness>0</spring_stiffness>
        </dynamics>
      </axis>
    </joint>
    <link name='right_wheel'>
      <pose relative_to='base_right_wheel_joint'>0 0 0 0 -0 0</pose>
      <inertial>
        <pose>0 0 0 0 -0 0</pose>
        <mass>0.1</mass>
        <inertia>
          <ixx>1e-05</ixx>
          <ixy>0</ixy>
          <ixz>0</ixz>
          <iyy>1e-05</iyy>
          <iyz>0</iyz>
          <izz>2e-05</izz>
        </inertia>
      </inertial>
      <collision name='right_wheel_collision'>
        <pose>0 0 0 0 -0 0</pose>
        <geometry>
          <cylinder>
            <length>0.27</length>
            <radius>0.387</radius>
          </cylinder>
        </geometry>
        <surface>
          <contact>
            <ode>
              <kp>1000</kp>
              <kd>100</kd>
            </ode>
          </contact>
          <friction>
            <ode>
              <mu>1</mu>
              <mu2>1</mu2>
            </ode>
          </friction>
        </surface>
      </collision>
      <visual name='right_wheel_visual'>
        <pose>0 0 0 0 -0 0</pose>
        <geometry>
          <cylinder>
            <length>0.27</length>
            <radius>0.387</radius>
          </cylinder>
        </geometry>
      </visual>
    </link>
  </model>
</sdf>
