<?xml version="1.0" ?>
<!-- =================================================================================== -->
<!-- |    This document was autogenerated by xacro from /home/soham/line_follower_ws/src/line_follower_world/models/robot.urdf.xacro | -->
<!-- |    EDITING THIS FILE BY HAND IS NOT RECOMMENDED                                 | -->
<!-- =================================================================================== -->
<robot name="FLF">
  <material name="grey">
    <color rgba="0.7 0.7 0.7 1"/>
  </material>
  <material name="green">
    <color rgba="0 0.6 0.0 1"/>
  </material>
  <material name="white">
    <color rgba="1 1 1 1"/>
  </material>
  <!-- Base Link -->
  <link name="base_link">
    <visual>
      <geometry>
        <box size="0.08 0.15 0.005"/>
      </geometry>
      <origin rpy="0 0 0" xyz="0 0 0"/>
      <material name="green"/>
    </visual>
  </link>
  <!-- Neck Link -->
  <link name="neck_link">
    <visual>
      <geometry>
        <box size="0.085 0.05 0.005"/>
      </geometry>
      <origin rpy="0 0 0" xyz="0.0825 0 0"/>
      <material name="green"/>
    </visual>
  </link>
  <!-- Sensor Link -->
  <link name="ir_link">
    <visual>
      <geometry>
        <box size="0.045 0.135 0.005"/>
      </geometry>
      <origin rpy="0 0 0" xyz="0.1475 0 0"/>
      <material name="green"/>
    </visual>
  </link>
  <!-- Left Wheel -->
  <link name="left_wheel">
    <visual>
      <geometry>
        <cylinder length="0.015" radius="0.0215"/>
      </geometry>
      <origin rpy="1.57 0 0" xyz="0 0.0825 0"/>
      <material name="white"/>
    </visual>
  </link>
  <!-- Right Wheel -->
  <link name="right_wheel">
    <visual>
      <geometry>
        <cylinder length="0.015500000000000002" radius="0.0215"/>
      </geometry>
      <origin rpy="1.57 0 0" xyz="0 -0.0825 0"/>
      <material name="white"/>
    </visual>
  </link>
  <!-- Joints -->
  <joint name="base_neck_joint" type="fixed">
    <parent link="base_link"/>
    <child link="neck_link"/>
  </joint>
  <joint name="base_ir_joint" type="fixed">
    <parent link="base_link"/>
    <child link="ir_link"/>
  </joint>
  <joint name="base_left_wheel_joint" type="continuous">
    <parent link="base_link"/>
    <child link="left_wheel"/>
  </joint>
  <joint name="base_right_wheel_joint" type="continuous">
    <parent link="base_link"/>
    <child link="right_wheel"/>
  </joint>
</robot>
