<?xml version="1.0" ?>
<!-- =================================================================================== -->
<!-- |    This document was autogenerated by xacro from /home/soham/line_follower_ws/src/line_follower_robot/urdf/my_robot/robot.urdf.xacro | -->
<!-- |    EDITING THIS FILE BY HAND IS NOT RECOMMENDED                                 | -->
<!-- =================================================================================== -->
<robot name="FLF">
  <material name="grey">
    <color rgba="0.7 0.7 0.7 1"/>
  </material>
  <material name="green">
    <color rgba="0 0.6 0.0 1"/>
  </material>
  <material name="white">
    <color rgba="1 1 1 1"/>
  </material>
  <!-- Base Footprint Link -->
  <link name="base_footprint"/>
  <!-- Base Link -->
  <link name="base_link">
    <visual>
      <geometry>
        <box size="1.44 2.6999999999999997 0.09"/>
      </geometry>
      <origin rpy="0 0 0" xyz="0 0 0"/>
      <material name="green"/>
    </visual>
    <collision>
      <geometry>
        <box size="1.44 2.6999999999999997 0.09"/>
      </geometry>
      <origin rpy="0 0 0" xyz="0 0 0"/>
    </collision>
    <inertial>
      <mass value="2.0"/>
      <origin rpy="0 0 0" xyz="0 0 0"/>
      <inertia ixx="0.01" ixy="0.0" ixz="0.0" iyy="0.01" iyz="0.0" izz="0.01"/>
    </inertial>
  </link>
  <!-- test -->
  <link name="test_link">
    <visual>
      <geometry>
        <box size="0.18 0.54 0.8999999999999999"/>
      </geometry>
      <material name="blue">
        <color rgba="0 0 1 1"/>
      </material>
    </visual>
  </link>
  <!-- test -->
  <!-- Neck Link -->
  <link name="neck_link">
    <visual>
      <geometry>
        <box size="1.53 0.8999999999999999 0.09"/>
      </geometry>
      <origin rpy="0 0 0" xyz="0 0 0"/>
      <material name="green"/>
    </visual>
    <collision>
      <geometry>
        <box size="1.53 0.8999999999999999 0.09"/>
      </geometry>
      <origin rpy="0 0 0" xyz="0 0 0"/>
    </collision>
    <inertial>
      <mass value="2.0"/>
      <origin rpy="0 0 0" xyz="0 0 0"/>
      <inertia ixx="0.01" ixy="0.0" ixz="0.0" iyy="0.01" iyz="0.0" izz="0.01"/>
    </inertial>
  </link>
  <!-- IR Sensor Link -->
  <link name="ir_link">
    <visual>
      <geometry>
        <box size="0.8099999999999999 2.4299999999999997 0.09"/>
      </geometry>
      <origin rpy="0 0 0" xyz="0 0 0"/>
      <material name="green"/>
    </visual>
    <collision>
      <geometry>
        <box size="0.8099999999999999 2.4299999999999997 0.09"/>
      </geometry>
      <origin rpy="0 0 0" xyz="0 0 0"/>
    </collision>
    <inertial>
      <mass value="2.0"/>
      <origin rpy="0 0 0" xyz="0 0 0"/>
      <inertia ixx="0.01" ixy="0.0" ixz="0.0" iyy="0.01" iyz="0.0" izz="0.01"/>
    </inertial>
  </link>
  <!-- IR Sensor 1 -->
  <link name="ir_sensor_1">
    <visual>
      <geometry>
        <box size=" 0.054 0.054 0.18"/>
      </geometry>
      <origin rpy="0 0 0" xyz="0.0 0 0.09"/>
      <material name="white"/>
    </visual>
    <collision>
      <geometry>
        <box size="0.18 0.054 0.054"/>
      </geometry>
      <origin rpy="0 0 0" xyz="0.09 0 0"/>
    </collision>
    <inertial>
      <mass value="0.1"/>
      <origin xyz="0 0 0"/>
      <inertia ixx="0.0001" ixy="0" ixz="0" iyy="0.0001" iyz="0" izz="0.0001"/>
    </inertial>
  </link>
  <link name="ir_sensor_2">
    <visual>
      <geometry>
        <box size="0.054 0.054 0.18"/>
      </geometry>
      <origin rpy="0 0 0" xyz="0.0 0 0.09"/>
      <material name="white"/>
    </visual>
    <collision>
      <geometry>
        <box size="0.18 0.054 0.054"/>
      </geometry>
      <origin rpy="0 0 0" xyz="0 0 0"/>
    </collision>
    <inertial>
      <mass value="0.1"/>
      <origin xyz="0 0 0"/>
      <inertia ixx="0.0001" ixy="0" ixz="0" iyy="0.0001" iyz="0" izz="0.0001"/>
    </inertial>
  </link>
  <link name="ir_sensor_3">
    <visual>
      <geometry>
        <box size="0.054 0.054 0.18"/>
      </geometry>
      <origin rpy="0 0 0" xyz="0.0 0 0.09"/>
      <material name="white"/>
    </visual>
    <collision>
      <geometry>
        <box size="0.18 0.054 0.054"/>
      </geometry>
      <origin rpy="0 0 0" xyz="0 0 0"/>
    </collision>
    <inertial>
      <mass value="0.1"/>
      <origin xyz="0 0 0"/>
      <inertia ixx="0.0001" ixy="0" ixz="0" iyy="0.0001" iyz="0" izz="0.0001"/>
    </inertial>
  </link>
  <link name="ir_sensor_4">
    <visual>
      <geometry>
        <box size="0.054 0.054 0.18"/>
      </geometry>
      <origin rpy="0 0 0" xyz="0.0 0 0.09"/>
      <material name="white"/>
    </visual>
    <collision>
      <geometry>
        <box size="0.18 0.054 0.054"/>
      </geometry>
      <origin rpy="0 0 0" xyz="0 0 0"/>
    </collision>
    <inertial>
      <mass value="0.1"/>
      <origin xyz="0 0 0"/>
      <inertia ixx="0.0001" ixy="0" ixz="0" iyy="0.0001" iyz="0" izz="0.0001"/>
    </inertial>
  </link>
  <link name="ir_sensor_5">
    <visual>
      <geometry>
        <box size="0.054 0.054 0.18"/>
      </geometry>
      <origin rpy="0 0 0" xyz="0.0 0 0.09"/>
      <material name="white"/>
    </visual>
    <collision>
      <geometry>
        <box size="0.18 0.054 0.054"/>
      </geometry>
      <origin rpy="0 0 0" xyz="0 0 0"/>
    </collision>
    <inertial>
      <mass value="0.1"/>
      <origin xyz="0 0 0"/>
      <inertia ixx="0.0001" ixy="0" ixz="0" iyy="0.0001" iyz="0" izz="0.0001"/>
    </inertial>
  </link>
  <!-- Left Wheel -->
  <link name="left_wheel">
    <visual>
      <geometry>
        <cylinder length="0.27" radius="0.38699999999999996"/>
      </geometry>
      <origin rpy="0 0 0" xyz="0 0 0"/>
      <material name="white"/>
    </visual>
    <collision>
      <geometry>
        <cylinder length="0.27" radius="0.38699999999999996"/>
      </geometry>
      <origin rpy="0 0 0" xyz="0 0 0"/>
    </collision>
    <inertial>
      <mass value="0.1"/>
      <origin rpy="0 0 0" xyz="0 0 0"/>
      <inertia ixx="0.00001" ixy="0.0" ixz="0.0" iyy="0.00001" iyz="0.0" izz="0.00002"/>
    </inertial>
  </link>
  <!-- Right Wheel -->
  <link name="right_wheel">
    <visual>
      <geometry>
        <cylinder length="0.27" radius="0.38699999999999996"/>
      </geometry>
      <origin rpy="0 0 0" xyz="0 0 0"/>
      <material name="white"/>
    </visual>
    <collision>
      <geometry>
        <cylinder length="0.27" radius="0.38699999999999996"/>
      </geometry>
      <origin rpy="0 0 0" xyz="0 0 0"/>
    </collision>
    <inertial>
      <mass value="0.1"/>
      <origin rpy="0 0 0" xyz="0 0 0"/>
      <inertia ixx="0.00001" ixy="0.0" ixz="0.0" iyy="0.00001" iyz="0.0" izz="0.00002"/>
    </inertial>
  </link>
  <link name="caster_wheel">
    <visual>
      <geometry>
        <sphere radius="0.18"/>
        <!-- Radius = 1.075, so diameter = 2.15 -->
      </geometry>
      <material name="white"/>
    </visual>
    <collision>
      <geometry>
        <sphere radius="0.18"/>
      </geometry>
      <surface>
        <contact>
          <collide_bitmask>0x02</collide_bitmask>
        </contact>
      </surface>
    </collision>
    <inertial>
      <mass value="0.05"/>
      <origin xyz="0 0 0"/>
      <inertia ixx="0.001" ixy="0" ixz="0" iyy="0.001" iyz="0" izz="0.001"/>
    </inertial>
  </link>
  <!-- Joints -->
  <joint name="base_footprint_joint" type="fixed">
    <parent link="base_footprint"/>
    <child link="base_link"/>
    <origin rpy="0 0 0" xyz="0 0 0.38699999999999996"/>
  </joint>
  <joint name="base_neck_joint" type="fixed">
    <parent link="base_link"/>
    <child link="neck_link"/>
    <origin rpy="0 0 0" xyz="1.4849999999999999 0 0"/>
  </joint>
  <joint name="base_ir_joint" type="fixed">
    <parent link="base_link"/>
    <child link="ir_link"/>
    <origin rpy="0 0 0" xyz="2.655 0 0"/>
  </joint>
  <joint name="base_left_wheel_joint" type="continuous">
    <parent link="base_link"/>
    <child link="left_wheel"/>
    <origin rpy="-1.5707963267948966 0 0" xyz="0 1.4849999999999999 0"/>
    <axis xyz="0 0 1"/>
    <dynamics damping="0.5" friction="0.5"/>
  </joint>
  <joint name="base_right_wheel_joint" type="continuous">
    <parent link="base_link"/>
    <child link="right_wheel"/>
    <origin rpy="-1.5707963267948966 0 0" xyz="0 -1.4849999999999999 0"/>
    <axis xyz="0 0 1"/>
    <dynamics damping="0.5" friction="0.5"/>
  </joint>
  <!-- Joint to Attach Caster to Neck -->
  <joint name="caster_joint" type="fixed">
    <parent link="neck_link"/>
    <child link="caster_wheel"/>
    <origin rpy="0 0 0" xyz="0 0 -0.243"/>
    <!-- Places caster exactly on the ground -->
  </joint>
  <joint name="ir_sensor_1_joint" type="fixed">
    <parent link="ir_link"/>
    <child link="ir_sensor_1"/>
    <origin rpy="0 1.57 0" xyz="0.0 0 -0.072"/>
  </joint>
  <joint name="ir_sensor_2_joint" type="fixed">
    <parent link="ir_link"/>
    <child link="ir_sensor_2"/>
    <origin rpy="0 1.57 0" xyz="0.0 0.486 -0.072"/>
  </joint>
  <joint name="ir_sensor_3_joint" type="fixed">
    <parent link="ir_link"/>
    <child link="ir_sensor_3"/>
    <origin rpy="0 1.57 0" xyz="0.0 0.972 -0.072"/>
  </joint>
  <joint name="ir_sensor_4_joint" type="fixed">
    <parent link="ir_link"/>
    <child link="ir_sensor_4"/>
    <origin rpy="0 1.57 0" xyz="0.0 -0.486 -0.072"/>
  </joint>
  <joint name="ir_sensor_5_joint" type="fixed">
    <parent link="ir_link"/>
    <child link="ir_sensor_5"/>
    <origin rpy="0 1.57 0" xyz="0.0 -0.972 -0.072"/>
  </joint>
  <!--test joiont -->
  <joint name="test_joint" type="fixed">
    <parent link="base_link"/>
    <child link="test_link"/>
    <origin rpy="0 1.57 0" xyz="0 0 0.46259999999999996"/>
  </joint>
  <!--test joiont -->
  <!-- Gazebo specific elements -->
  <gazebo reference="left_wheel">
    <material>Gazebo/Blue</material>
    <mu1>1.0</mu1>
    <mu2>1.0</mu2>
    <kp>1000.0</kp>
    <kd>100.0</kd>
    <fdir1>1 0 0</fdir1>
  </gazebo>
  <gazebo reference="right_wheel">
    <material>Gazebo/Blue</material>
    <mu1>1.0</mu1>
    <mu2>1.0</mu2>
    <kp>1000.0</kp>
    <kd>100.0</kd>
    <fdir1>1 0 0</fdir1>
  </gazebo>
  <gazebo reference="caster_wheel">
    <material>Gazebo/Blue</material>
    <mu1>0.000005</mu1>
    <mu2>0.000005</mu2>
  </gazebo>
  <!-- IR sensor plugins -->
  <!--test pugin-->
  <gazebo reference="test_link">
    <sensor name="test_sensor" type="ray">
      <update_rate>30</update_rate>
      <visualize>true</visualize>
      <ray>
        <scan>
          <horizontal>
            <samples>10</samples>
            <resolution>1</resolution>
            <min_angle>-0.1</min_angle>
            <max_angle>0.1</max_angle>
          </horizontal>
        </scan>
        <range>
          <min>0.01</min>
          <max>1.0</max>
          <resolution>0.01</resolution>
        </range>
      </ray>
      <plugin filename="libgazebo_ros_ray_sensor.so" name="sensor_plugin">
        <ros>
          <namespace>/</namespace>
          <remapping>~/out:=/test_sensor</remapping>
        </ros>
        <output_type>sensor_msgs/LaserScan</output_type>
        <frame_name>sensor_link</frame_name>
      </plugin>
    </sensor>
  </gazebo>
  <!--test pugin-->
  <gazebo reference="ir_sensor_1">
    <sensor name="ir_sensor_1" type="ray">
      <update_rate>30</update_rate>
      <visualize>true</visualize>
      <ray>
        <scan>
          <horizontal>
            <samples>10</samples>
            <resolution>1</resolution>
            <min_angle>-0.1</min_angle>
            <max_angle>0.1</max_angle>
          </horizontal>
        </scan>
        <range>
          <min>0.3</min>
          <max>2</max>
          <resolution>0.01</resolution>
        </range>
      </ray>
      <plugin filename="libgazebo_ros_ray_sensor.so" name="ir_sensor_1_plugin">
        <ros>
          <namespace>/</namespace>
          <remapping>~/out:=/ir_sensor_1</remapping>
        </ros>
        <output_type>sensor_msgs/LaserScan</output_type>
        <frame_name>ir_sensor_1</frame_name>
      </plugin>
    </sensor>
  </gazebo>
  <gazebo reference="ir_sensor_2">
    <sensor name="ir_sensor_2" type="ray">
      <update_rate>30</update_rate>
      <visualize>true</visualize>
      <ray>
        <scan>
          <horizontal>
            <samples>10</samples>
            <resolution>1</resolution>
            <min_angle>-0.1</min_angle>
            <max_angle>0.1</max_angle>
          </horizontal>
        </scan>
        <range>
          <min>0.3</min>
          <max>2</max>
          <resolution>0.01</resolution>
        </range>
      </ray>
      <plugin filename="libgazebo_ros_ray_sensor.so" name="ir_sensor_2_plugin">
        <ros>
          <namespace>/</namespace>
          <remapping>~/out:=/ir_sensor_2</remapping>
        </ros>
        <output_type>sensor_msgs/LaserScan</output_type>
        <frame_name>ir_sensor_2</frame_name>
      </plugin>
    </sensor>
  </gazebo>
  <gazebo reference="ir_sensor_3">
    <sensor name="ir_sensor_3" type="ray">
      <update_rate>30</update_rate>
      <visualize>true</visualize>
      <ray>
        <scan>
          <horizontal>
            <samples>10</samples>
            <resolution>1</resolution>
            <min_angle>-0.1</min_angle>
            <max_angle>0.1</max_angle>
          </horizontal>
        </scan>
        <range>
          <min>0.3</min>
          <max>2</max>
          <resolution>0.01</resolution>
        </range>
      </ray>
      <plugin filename="libgazebo_ros_ray_sensor.so" name="ir_sensor_3_plugin">
        <ros>
          <namespace>/</namespace>
          <remapping>~/out:=/ir_sensor_3</remapping>
        </ros>
        <output_type>sensor_msgs/LaserScan</output_type>
        <frame_name>ir_sensor_3</frame_name>
      </plugin>
    </sensor>
  </gazebo>
  <gazebo reference="ir_sensor_4">
    <sensor name="ir_sensor_4" type="ray">
      <update_rate>30</update_rate>
      <visualize>true</visualize>
      <ray>
        <scan>
          <horizontal>
            <samples>10</samples>
            <resolution>1</resolution>
            <min_angle>-0.1</min_angle>
            <max_angle>0.1</max_angle>
          </horizontal>
        </scan>
        <range>
          <min>0.3</min>
          <max>2</max>
          <resolution>0.01</resolution>
        </range>
      </ray>
      <plugin filename="libgazebo_ros_ray_sensor.so" name="ir_sensor_4_plugin">
        <ros>
          <namespace>/</namespace>
          <remapping>~/out:=/ir_sensor_4</remapping>
        </ros>
        <output_type>sensor_msgs/LaserScan</output_type>
        <frame_name>ir_sensor_4</frame_name>
      </plugin>
    </sensor>
  </gazebo>
  <gazebo reference="ir_sensor_5">
    <sensor name="ir_sensor_5" type="ray">
      <update_rate>30</update_rate>
      <visualize>true</visualize>
      <ray>
        <scan>
          <horizontal>
            <samples>10</samples>
            <resolution>1</resolution>
            <min_angle>-0.1</min_angle>
            <max_angle>0.1</max_angle>
          </horizontal>
        </scan>
        <range>
          <min>0.3</min>
          <max>2</max>
          <resolution>0.01</resolution>
        </range>
      </ray>
      <plugin filename="libgazebo_ros_ray_sensor.so" name="ir_sensor_5_plugin">
        <ros>
          <namespace>/</namespace>
          <remapping>~/out:=/ir_sensor_5</remapping>
        </ros>
        <output_type>sensor_msgs/LaserScan</output_type>
        <frame_name>ir_sensor_5</frame_name>
      </plugin>
    </sensor>
  </gazebo>
  <gazebo>
    <plugin filename="libgazebo_ros_diff_drive.so" name="differential_drive_controller">
      <update_rate>30</update_rate>
      <left_joint>base_left_wheel_joint</left_joint>
      <right_joint>base_right_wheel_joint</right_joint>
      <wheel_separation>2.9699999999999998</wheel_separation>
      <wheel_diameter>0.7739999999999999</wheel_diameter>
      <max_wheel_acceleration>1.0</max_wheel_acceleration>
      <max_wheel_torque>20</max_wheel_torque>
      <command_topic>cmd_vel</command_topic>
      <publish_odom>true</publish_odom>
      <publish_odom_tf>true</publish_odom_tf>
      <odometry_topic>odom</odometry_topic>
      <odometry_frame>odom</odometry_frame>
      <robot_base_frame>base_link</robot_base_frame>
    </plugin>
  </gazebo>
</robot>
