<?xml version="1.0"?>
<robot name="FLF" xmlns:xacro="http://www.ros.org/wiki/xacro">
<!-- Scaling Factor -->
<xacro:property name="scale" value="0.18"/>
<material name="grey">
<color rgba="0.7 0.7 0.7 1"/>
</material>
<material name="green">
<color rgba="0 0.6 0.0 1"/>
</material>
<material name="white">
<color rgba="1 1 1 1"/>
</material>


<!-- Base Footprint Link -->
<link name="base_footprint" />
<!-- Base Link -->
<link name="base_link">
<visual>
<geometry>
<box size="${8 * scale} ${15 * scale} ${0.5 * scale}"/>
</geometry>
<origin xyz="0 0 0" rpy="0 0 0"/>
<material name="green"/>
</visual>
<collision>
<geometry>
<box size="${8 * scale} ${15 * scale} ${0.5 * scale}"/>
</geometry>
<origin xyz="0 0 0" rpy="0 0 0"/>
</collision>
<inertial>
<mass value="2.0"/>
<origin xyz="0 0 0" rpy="0 0 0"/>
<inertia 
  ixx="0.01" ixy="0.0" ixz="0.0"
  iyy="0.01" iyz="0.0"
  izz="0.01"/>
</inertial>
</link>
<!-- test -->
  <link name="test_link">
    <visual>
      <geometry>
        <box size="${1*scale} ${3*scale} ${5*scale}"/>
      </geometry>
      <material name="blue">
        <color rgba="0 0 1 1"/>
      </material>
    </visual>
  </link>
<!-- test -->
<!-- Neck Link -->
<link name="neck_link">
<visual>
<geometry>
<box size="${8.5 * scale} ${5 * scale} ${0.5 * scale}"/>
</geometry>
<origin xyz="0 0 0" rpy="0 0 0"/>
<material name="green"/>
</visual>
<collision>
<geometry>
<box size="${8.5 * scale} ${5 * scale} ${0.5 * scale}"/>
</geometry>
<origin xyz="0 0 0" rpy="0 0 0"/>
</collision>
<inertial>
<mass value="2.0"/>
<origin xyz="0 0 0" rpy="0 0 0"/>
<inertia 
  ixx="0.01" ixy="0.0" ixz="0.0"
  iyy="0.01" iyz="0.0"
  izz="0.01"/>
</inertial>
</link>
<!-- IR Sensor Link -->
<link name="ir_link">
<visual>
<geometry>
<box size="${4.5 * scale} ${13.5 * scale} ${0.5 * scale}"/>
</geometry>
<origin xyz="0 0 0" rpy="0 0 0"/>
<material name="green"/>
</visual>
<collision>
<geometry>
<box size="${4.5 * scale} ${13.5 * scale} ${0.5 * scale}"/>
</geometry>
<origin xyz="0 0 0" rpy="0 0 0"/>
</collision>
<inertial>
<mass value="2.0"/>
<origin xyz="0 0 0" rpy="0 0 0"/>
<inertia 
  ixx="0.01" ixy="0.0" ixz="0.0"
  iyy="0.01" iyz="0.0"
  izz="0.01"/>
</inertial>
</link>
<!-- IR Sensor 1 -->
<link name="ir_sensor_1">
    <visual>
        <geometry>
            <box size=" ${0.3 * scale} ${0.3 * scale} ${1 * scale}"/>
        </geometry>
        <origin xyz="${0.0 * scale} 0 ${0.5 * scale}" rpy="0 0 0"/>
        <material name="white"/>
    </visual>
    <collision>
        <geometry>
            <box size="${1.0 * scale} ${0.3 * scale} ${0.3 * scale}"/>
        </geometry>
        <origin xyz="${0.5 * scale} 0 0" rpy="0 0 0"/>
    </collision>
    <inertial>
        <mass value="0.1"/>
        <origin xyz="0 0 0"/>
        <inertia ixx="0.0001" ixy="0" ixz="0" iyy="0.0001" iyz="0" izz="0.0001"/>
    </inertial>
</link>
<link name="ir_sensor_2">
    <visual>
        <geometry>
            <box size="${0.3 * scale} ${0.3 * scale} ${1 * scale}"/>
        </geometry>
        <origin xyz="${0.0 * scale} 0 ${0.5 * scale}" rpy="0 0 0"/>
        <material name="white"/>
    </visual>
    <collision>
        <geometry>
            <box size="${1.0 * scale} ${0.3 * scale} ${0.3 * scale}"/>
        </geometry>
        <origin xyz="0 0 0" rpy="0 0 0"/>
    </collision>
    <inertial>
        <mass value="0.1"/>
        <origin xyz="0 0 0"/>
        <inertia ixx="0.0001" ixy="0" ixz="0" iyy="0.0001" iyz="0" izz="0.0001"/>
    </inertial>
</link>
<link name="ir_sensor_3">
    <visual>
        <geometry>
            <box size="${0.3 * scale} ${0.3 * scale} ${1 * scale}"/>
        </geometry>
        <origin xyz="${0.0 * scale} 0 ${0.5 * scale}" rpy="0 0 0"/>
        <material name="white"/>
    </visual>
    <collision>
        <geometry>
            <box size="${1.0 * scale} ${0.3 * scale} ${0.3 * scale}"/>
        </geometry>
        <origin xyz="0 0 0" rpy="0 0 0"/>
    </collision>
    <inertial>
        <mass value="0.1"/>
        <origin xyz="0 0 0"/>
        <inertia ixx="0.0001" ixy="0" ixz="0" iyy="0.0001" iyz="0" izz="0.0001"/>
    </inertial>
</link>
<link name="ir_sensor_4">
    <visual>
        <geometry>
            <box size="${0.3 * scale} ${0.3 * scale} ${1 * scale}"/>
        </geometry>
        <origin xyz="${0.0 * scale} 0 ${0.5 * scale}" rpy="0 0 0"/>
        <material name="white"/>
    </visual>
    <collision>
        <geometry>
            <box size="${1.0 * scale} ${0.3 * scale} ${0.3 * scale}"/>
        </geometry>
        <origin xyz="0 0 0" rpy="0 0 0"/>
    </collision>
    <inertial>
        <mass value="0.1"/>
        <origin xyz="0 0 0"/>
        <inertia ixx="0.0001" ixy="0" ixz="0" iyy="0.0001" iyz="0" izz="0.0001"/>
    </inertial>
</link>
<link name="ir_sensor_5">
    <visual>
        <geometry>
            <box size="${0.3 * scale} ${0.3 * scale} ${1 * scale}"/>
        </geometry>
        <origin xyz="${0.0 * scale} 0 ${0.5 * scale}" rpy="0 0 0"/>
        <material name="white"/>
    </visual>
    <collision>
        <geometry>
            <box size="${1.0 * scale} ${0.3 * scale} ${0.3 * scale}"/>
        </geometry>
        <origin xyz="0 0 0" rpy="0 0 0"/>
    </collision>
    <inertial>
        <mass value="0.1"/>
        <origin xyz="0 0 0"/>
        <inertia ixx="0.0001" ixy="0" ixz="0" iyy="0.0001" iyz="0" izz="0.0001"/>
    </inertial>
</link>

<!-- Left Wheel -->
<link name="left_wheel">
<visual>
<geometry>
<cylinder radius="${2.15 * scale}" length="${1.5 * scale}"/>
</geometry>
<origin xyz="0 0 0" rpy="0 0 0"/>
<material name="white"/>
</visual>
<collision>
<geometry>
<cylinder radius="${2.15 * scale}" length="${1.5 * scale}"/>
</geometry>
<origin xyz="0 0 0" rpy="0 0 0"/>
</collision>
<inertial>
<mass value="0.1"/>
<origin xyz="0 0 0" rpy="0 0 0"/>
<inertia 
  ixx="0.00001" ixy="0.0" ixz="0.0"
  iyy="0.00001" iyz="0.0"
  izz="0.00002"/>
</inertial>
</link>
<!-- Right Wheel -->
<link name="right_wheel">
<visual>
<geometry>
<cylinder radius="${2.15 * scale}" length="${1.5 * scale}"/>
</geometry>
<origin xyz="0 0 0" rpy="0 0 0"/>
<material name="white"/>
</visual>
<collision>
<geometry>
<cylinder radius="${2.15 * scale}" length="${1.5 * scale}"/>
</geometry>
<origin xyz="0 0 0" rpy="0 0 0"/>
</collision>
<inertial>
<mass value="0.1"/>
<origin xyz="0 0 0" rpy="0 0 0"/>
<inertia 
  ixx="0.00001" ixy="0.0" ixz="0.0"
  iyy="0.00001" iyz="0.0"
  izz="0.00002"/>
</inertial>
</link>
<link name="caster_wheel">
    <visual>
        <geometry>
            <sphere radius="${1*scale}"/> <!-- Radius = 1.075, so diameter = 2.15 -->
        </geometry>
        <material name="white"/>
    </visual>
    <collision>
    
        <geometry>
            <sphere radius="${1*scale}"/>
        </geometry>
        <surface>
    <contact>
      <collide_bitmask>0x02</collide_bitmask>
    </contact>
  </surface>
    </collision>
    <inertial>
        <mass value="0.05"/>
        <origin xyz="0 0 0"/>
        <inertia ixx="0.001" iyy="0.001" izz="0.001" ixy="0" ixz="0" iyz="0"/>
    </inertial>
</link>
<!-- Joints -->
<joint name="base_footprint_joint" type="fixed">
<parent link="base_footprint"/>
<child link="base_link"/>
<origin xyz="0 0 ${2.15 * scale}" rpy="0 0 0"/>
</joint>
<joint name="base_neck_joint" type="fixed">
<parent link="base_link"/>
<child link="neck_link"/>
<origin xyz="${8.25 * scale} 0 0" rpy="0 0 0"/>
</joint>
<joint name="base_ir_joint" type="fixed">
<parent link="base_link"/>
<child link="ir_link"/>
<origin xyz="${14.75 * scale} 0 0" rpy="0 0 0"/>
</joint>
<joint name="base_left_wheel_joint" type="continuous">
  <parent link="base_link"/>
  <child link="left_wheel"/>
  <origin xyz="0 ${(8.25 * scale)} 0" rpy="${-pi/2} 0 0"/>
  <axis xyz="0 0 1"/>
    <dynamics damping="0.5" friction="0.5"/>
</joint>

<joint name="base_right_wheel_joint" type="continuous">
  <parent link="base_link"/>
  <child link="right_wheel"/>
  <origin xyz="0 ${(-8.25 * scale)} 0" rpy="${-pi/2} 0 0"/>
  <axis xyz="0 0 1"/>
    <dynamics damping="0.5" friction="0.5"/>
</joint>
<!-- Joint to Attach Caster to Neck -->
<joint name="caster_joint" type="fixed">
    <parent link="neck_link"/>
    <child link="caster_wheel"/>
    <origin xyz="0 0 ${-1.35*scale}" rpy="0 0 0"/> <!-- Places caster exactly on the ground -->
</joint>
<joint name="ir_sensor_1_joint" type="fixed">
    <parent link="ir_link"/>
    <child link="ir_sensor_1"/>
    <origin xyz="${0 * scale} 0 ${-0.40 * scale}" rpy="0 1.57 0"/></joint>
<joint name="ir_sensor_2_joint" type="fixed">
    <parent link="ir_link"/>
    <child link="ir_sensor_2"/>
    <origin xyz="${0 * scale} ${2.7 * scale} ${-0.40 * scale}" rpy="0 1.57 0"/></joint>
<joint name="ir_sensor_3_joint" type="fixed">
    <parent link="ir_link"/>
    <child link="ir_sensor_3"/>
    <origin xyz="${0 * scale} ${2 * 2.7 * scale} ${-0.40 * scale}" rpy="0 1.57 0"/></joint>
<joint name="ir_sensor_4_joint" type="fixed">
    <parent link="ir_link"/>
    <child link="ir_sensor_4"/>
    <origin xyz="${0 * scale} ${-2.7 * scale} ${-0.40 * scale}" rpy="0 1.57 0"/></joint>
<joint name="ir_sensor_5_joint" type="fixed">
    <parent link="ir_link"/>
    <child link="ir_sensor_5"/>
    <origin xyz="${0 * scale} ${2 * -2.7 * scale} ${-0.40 * scale}" rpy="0 1.57 0"/></joint>

<!--test joiont -->
  <joint name="test_joint" type="fixed">
    <parent link="base_link"/>
    <child link="test_link"/>
    <origin xyz="0 0 ${2.57*scale}" rpy="0 1.57 0"/>
  </joint>

<!--test joiont -->

<!-- Gazebo specific elements -->
<gazebo reference="left_wheel">
<material>Gazebo/Blue</material>
  <mu1>1.0</mu1>  
  <mu2>1.0</mu2>  
  <kp>1000.0</kp>  
  <kd>100.0</kd>
  <fdir1>1 0 0</fdir1>
</gazebo>

<gazebo reference="right_wheel">
<material>Gazebo/Blue</material>
  <mu1>1.0</mu1>
  <mu2>1.0</mu2>
  <kp>1000.0</kp>
  <kd>100.0</kd>
  <fdir1>1 0 0</fdir1>
</gazebo>

<gazebo reference="caster_wheel">
<material>Gazebo/Blue</material>
  <mu1>0.000005</mu1>
  <mu2>0.000005</mu2>
</gazebo>

<!-- IR sensor plugins -->
<!--test pugin-->
  <gazebo reference="test_link">
    <sensor type="ray" name="test_sensor">
      <update_rate>30</update_rate>
      <visualize>true</visualize>
      <ray>
        <scan>
          <horizontal>
            <samples>10</samples>
            <resolution>1</resolution>
            <min_angle>-0.1</min_angle>
            <max_angle>0.1</max_angle>
          </horizontal>
        </scan>
        <range>
          <min>0.01</min>
          <max>1.0</max>
          <resolution>0.01</resolution>
        </range>
      </ray>
      <plugin name="sensor_plugin" filename="libgazebo_ros_ray_sensor.so">
  <ros>
    <namespace>/</namespace>
    <remapping>~/out:=/test_sensor</remapping>
  </ros>
  <output_type>sensor_msgs/LaserScan</output_type>
  <frame_name>sensor_link</frame_name>
</plugin>
    </sensor>
  </gazebo>
<!--test pugin-->

<gazebo reference="ir_sensor_1">
  <sensor type="ray" name="ir_sensor_1">
    <update_rate>30</update_rate>
          <visualize>true</visualize>
    <ray>
        <scan>
          <horizontal>
            <samples>10</samples>
            <resolution>1</resolution>
            <min_angle>-0.1</min_angle>
            <max_angle>0.1</max_angle>
          </horizontal>
        </scan>
        <range>
          <min>0.3</min>
          <max>2</max>
          <resolution>0.01</resolution>
        </range>
      </ray>
    <plugin name="ir_sensor_1_plugin" filename="libgazebo_ros_ray_sensor.so">
      <ros>
        <namespace>/</namespace>

          <remapping>~/out:=/ir_sensor_1</remapping>

      </ros>
      <output_type>sensor_msgs/LaserScan</output_type>
      <frame_name>ir_sensor_1</frame_name>
    </plugin>
  </sensor>
</gazebo>

<gazebo reference="ir_sensor_2">
  <sensor type="ray" name="ir_sensor_2">
    <update_rate>30</update_rate>
          <visualize>true</visualize>

    <ray>
        <scan>
          <horizontal>
            <samples>10</samples>
            <resolution>1</resolution>
            <min_angle>-0.1</min_angle>
            <max_angle>0.1</max_angle>
          </horizontal>
        </scan>
        <range>
          <min>0.3</min>
          <max>2</max>
          <resolution>0.01</resolution>
        </range>
      </ray>
    <plugin name="ir_sensor_2_plugin" filename="libgazebo_ros_ray_sensor.so">
      <ros>
        <namespace>/</namespace>

          <remapping>~/out:=/ir_sensor_2</remapping>

      </ros>
      <output_type>sensor_msgs/LaserScan</output_type>
      <frame_name>ir_sensor_2</frame_name>
    </plugin>
  </sensor>
</gazebo>

<gazebo reference="ir_sensor_3">
  <sensor type="ray" name="ir_sensor_3">
    <update_rate>30</update_rate>
    <visualize>true</visualize>

    <ray>
        <scan>
          <horizontal>
            <samples>10</samples>
            <resolution>1</resolution>
            <min_angle>-0.1</min_angle>
            <max_angle>0.1</max_angle>
          </horizontal>
        </scan>
        <range>
          <min>0.3</min>
          <max>2</max>
          <resolution>0.01</resolution>
        </range>
      </ray>
    <plugin name="ir_sensor_3_plugin" filename="libgazebo_ros_ray_sensor.so">
      <ros>
        <namespace>/</namespace>

          <remapping>~/out:=/ir_sensor_3</remapping>

      </ros>
      <output_type>sensor_msgs/LaserScan</output_type>
      <frame_name>ir_sensor_3</frame_name>
    </plugin>
  </sensor>
</gazebo>

<gazebo reference="ir_sensor_4">
  <sensor type="ray" name="ir_sensor_4">
    <update_rate>30</update_rate>
      <visualize>true</visualize>

    <ray>
        <scan>
          <horizontal>
            <samples>10</samples>
            <resolution>1</resolution>
            <min_angle>-0.1</min_angle>
            <max_angle>0.1</max_angle>
          </horizontal>
        </scan>
        <range>
          <min>0.3</min>
          <max>2</max>
          <resolution>0.01</resolution>
        </range>
      </ray>
    <plugin name="ir_sensor_4_plugin" filename="libgazebo_ros_ray_sensor.so">
      <ros>
        <namespace>/</namespace>

          <remapping>~/out:=/ir_sensor_4</remapping>

      </ros>
      <output_type>sensor_msgs/LaserScan</output_type>
      <frame_name>ir_sensor_4</frame_name>
    </plugin>
  </sensor>
</gazebo>

<gazebo reference="ir_sensor_5">
  <sensor type="ray" name="ir_sensor_5">
    <update_rate>30</update_rate>
          <visualize>true</visualize>

    <ray>
        <scan>
          <horizontal>
            <samples>10</samples>
            <resolution>1</resolution>
            <min_angle>-0.1</min_angle>
            <max_angle>0.1</max_angle>
          </horizontal>
        </scan>
        <range>
          <min>0.3</min>
          <max>2</max>
          <resolution>0.01</resolution>
        </range>
      </ray>
    <plugin name="ir_sensor_5_plugin" filename="libgazebo_ros_ray_sensor.so">
      <ros>
        <namespace>/</namespace>

          <remapping>~/out:=/ir_sensor_5</remapping>

      </ros>
      <output_type>sensor_msgs/LaserScan</output_type>
      <frame_name>ir_sensor_5</frame_name>
    </plugin>
  </sensor>
</gazebo>

<gazebo>
  <plugin name="differential_drive_controller" filename="libgazebo_ros_diff_drive.so">
    <update_rate>30</update_rate>
    <left_joint>base_left_wheel_joint</left_joint>
    <right_joint>base_right_wheel_joint</right_joint>
    <wheel_separation>${8.25 * 2 * scale}</wheel_separation>
    <wheel_diameter>${2.15 * 2 * scale}</wheel_diameter>
    <max_wheel_acceleration>1.0</max_wheel_acceleration>
    <max_wheel_torque>20</max_wheel_torque>
    <command_topic>cmd_vel</command_topic>
    <publish_odom>true</publish_odom>
    <publish_odom_tf>true</publish_odom_tf>
    <odometry_topic>odom</odometry_topic>
    <odometry_frame>odom</odometry_frame>
    <robot_base_frame>base_link</robot_base_frame>
  </plugin>
</gazebo>
</robot>

